Workbook

Sheet 持仓总表
A1: 小组波段汇总表
A2: 序号 | B2: 股票名称 | C2: 盈亏比例 | D2: 持仓成本 | E2: 持仓市值 | F2: 持仓股数 | G2: 现价 | H2: 成本价 | I2: 盈亏额 | K2: 资金总额 | L2: 资金余额
A3: 1 | B3: 国光电气 | C3: =I3/D3 | D3: =H3*F3 | E3: =G3*F3 | F3: 6800 | G3: 125.8 | H3: 76.47 | I3: =E3-H3*F3 | K3: 5000000 | L3: =K3-D203 | M3: =IF(L3<=0,"余额不足","")
A4: 2 | B4: 宏微科技 | C4: =I4/D4 | D4: =H4*F4 | E4: =G4*F4 | F4: 13800 | G4: 31.17 | H4: 27.41 | I4: =E4-H4*F4
A5: 3 | B5: 联创光电 | C5: =I5/D5 | D5: =H5*F5 | E5: =G5*F5 | F5: 5500 | G5: 70.73 | H5: 71.03 | I5: =E5-H5*F5 | K5: 股票名称 | L5: 求和项:持仓股数 | M5: 求和项:持仓市值
A6: 4 | B6: 广立微 | C6: =I6/D6 | D6: =H6*F6 | E6: =G6*F6 | F6: 7300 | G6: 78.78 | H6: 75.23 | I6: =E6-H6*F6 | K6: 概伦电子 | L6: 2500 | M6: 84450
A7: 5 | B7: 华润微 | C7: =I7/D7 | D7: =H7*F7 | E7: =G7*F7 | F7: 6548 | G7: 60.33 | H7: 54.72 | I7: =E7-H7*F7 | K7: 广立微 | L7: 1300 | M7: 86502
A8: 6 | C8: =I8/D8 | D8: =H8*F8 | E8: =G8*F8 | G8: ERROR | I8: =E8-H8*F8 | K8: 国光电气 | L8: 7600 | M8: 703836
A9: 7 | B9: 斯达半导 | C9: =I9/D9 | D9: =H9*F9 | E9: =G9*F9 | F9: 3900 | G9: ERROR | H9: 101.61 | I9: =E9-H9*F9 | K9: 合锻智能 | L9: 8800 | M9: 200024
A10: 8 | B10: 士兰微 | C10: =I10/D10 | D10: =H10*F10 | E10: =G10*F10 | F10: 19300 | G10: ERROR | H10: 29.51 | I10: =E10-H10*F10 | K10: 宏微科技 | L10: 17700 | M10: 486573
A11: 9 | B11: 紫光国微 | C11: =I11/D11 | D11: =H11*F11 | E11: =G11*F11 | F11: 1300 | G11: ERROR | H11: 83.929919 | I11: =E11-H11*F11 | K11: 华润微 | L11: 2948 | M11: 160666
A12: 10 | B12: 概伦电子 | C12: =I12/D12 | D12: =H12*F12 | E12: =G12*F12 | F12: 2500 | G12: ERROR | H12: 40.436444 | I12: =E12-H12*F12 | K12: 联创光电 | L12: 6800 | M12: 400520
A13: 11 | B13: 中芯国际 | C13: =I13/D13 | D13: =H13*F13 | E13: =G13*F13 | F13: 8100 | G13: ERROR | H13: 124.25 | I13: =E13-H13*F13 | K13: 联芸科技 | L13: 3600 | M13: 157572
A14: 12 | C14: =I14/D14 | D14: =H14*F14 | E14: =G14*F14 | G14: ERROR | I14: =E14-H14*F14 | K14: 山东黄金 | L14: 5500 | M14: 200310
A15: 13 | B15: 联芸科技 | C15: =I15/D15 | D15: =H15*F15 | E15: =G15*F15 | F15: 3600 | G15: ERROR | H15: 55.45 | I15: =E15-H15*F15 | K15: 士兰微 | L15: 8400 | M15: 232428
A16: 14 | C16: =I16/D16 | D16: =H16*F16 | E16: =G16*F16 | G16: ERROR | I16: =E16-H16*F16 | K16: 斯达半导 | L16: 1900 | M16: 178676
A17: 15 | C17: =I17/D17 | D17: =H17*F17 | E17: =G17*F17 | G17: ERROR | I17: =E17-H17*F17 | K17: 中芯国际 | L17: 2400 | M17: 272712
A18: 16 | B18: 比亚迪 | C18: =I18/D18 | D18: =H18*F18 | E18: =G18*F18 | F18: 1000 | G18: ERROR | H18: 97.64 | I18: =E18-H18*F18 | K18: (空白) | M18: 0
A19: 17 | C19: =I19/D19 | D19: =H19*F19 | E19: =G19*F19 | G19: ERROR | I19: =E19-H19*F19 | K19: 梦洁股份 | L19: 45400 | M19: 190226
A20: 18 | C20: =I20/D20 | D20: =H20*F20 | E20: =G20*F20 | G20: ERROR | I20: =E20-H20*F20 | K20: 芯原股份 | L20: 3900 | M20: 487929
A21: 19 | C21: =I21/D21 | D21: =H21*F21 | E21: =G21*F21 | G21: ERROR | I21: =E21-H21*F21 | K21: 紫光国微 | L21: 1300 | M21: 98605
A22: 20 | C22: =I22/D22 | D22: =H22*F22 | E22: =G22*F22 | G22: ERROR | I22: =E22-H22*F22 | K22: 中微公司 | L22: 1200 | M22: 327264
A23: 21 | C23: =I23/D23 | D23: =H23*F23 | E23: =G23*F23 | G23: ERROR | I23: =E23-H23*F23 | K23: 奥联电子 | L23: 25300 | M23: 573804
A24: 22 | C24: =I24/D24 | D24: =H24*F24 | E24: =G24*F24 | G24: ERROR | I24: =E24-H24*F24 | K24: 通富微电 | L24: 1400 | M24: 50078
A25: 23 | C25: =I25/D25 | D25: =H25*F25 | E25: =G25*F25 | G25: ERROR | I25: =E25-H25*F25 | K25: 利仁科技 | L25: 5400 | M25: 165942
A26: 24 | C26: =I26/D26 | D26: =H26*F26 | E26: =G26*F26 | G26: ERROR | I26: =E26-H26*F26 | K26: 总计 | L26: 153348 | M26: 5058117
A27: 25 | C27: =I27/D27 | D27: =H27*F27 | E27: =G27*F27 | G27: ERROR | I27: =E27-H27*F27
A28: 26 | C28: =I28/D28 | D28: =H28*F28 | E28: =G28*F28 | G28: ERROR | I28: =E28-H28*F28
A29: 27 | C29: =I29/D29 | D29: =H29*F29 | E29: =G29*F29 | G29: ERROR | I29: =E29-H29*F29
A30: 28 | C30: =I30/D30 | D30: =H30*F30 | E30: =G30*F30 | G30: ERROR | I30: =E30-H30*F30
A31: 29 | C31: =I31/D31 | D31: =H31*F31 | E31: =G31*F31 | G31: ERROR | I31: =E31-H31*F31
A32: 30 | C32: =I32/D32 | D32: =H32*F32 | E32: =G32*F32 | G32: ERROR | I32: =E32-H32*F32
A33: 31 | C33: =I33/D33 | D33: =H33*F33 | E33: =G33*F33 | G33: ERROR | I33: =E33-H33*F33
A34: 32 | C34: =I34/D34 | D34: =H34*F34 | E34: =G34*F34 | G34: ERROR | I34: =E34-H34*F34
A35: 33 | C35: =I35/D35 | D35: =H35*F35 | E35: =G35*F35 | G35: ERROR | I35: =E35-H35*F35
A36: 34 | C36: =I36/D36 | D36: =H36*F36 | E36: =G36*F36 | G36: ERROR | I36: =E36-H36*F36
A37: 35 | C37: =I37/D37 | D37: =H37*F37 | E37: =G37*F37 | G37: ERROR | I37: =E37-H37*F37
A38: 36 | C38: =I38/D38 | D38: =H38*F38 | E38: =G38*F38 | G38: ERROR | I38: =E38-H38*F38
... A202: 200 | C202: =I202/D202 | D202: =H202*F202 | E202: =G202*F202 | G202: ERROR | I202: =E202-H202*F202
A203: 合计 | C203: =I203/D203 | D203: =SUBTOTAL(9,D3:D202) | E203: =SUM(E3:E202) | F203: =SUM(F3:F202) | G203: ERROR | I203: =SUM(I3:I202)
...

Sheet 当日交易记录
A1: 交易单号 | B1: 股票名称 | C1: 成交价格 | D1: 成交股数 | E1: 手续费 | F1: 交易收支 | G1: 当前持仓股数 | H1: 交易许可 | J1: 交易日期 | K1: =TODAY()
A2: 1 | E2: =IF(B2="","",IF(D2<=0,-C2*D2*2.5/10000,C2*D2*12.5/10000)) | F2: =IF(B2="","",C2*D2-E2) | G2: =IF(B2="","",IF(COUNTIF(盘中持仓!B:B,B2),VLOOKUP(B2,盘中持仓!B:D,3,0),0)) | H2: =IF(B2="","",IF(G2<>0,IF(G2>0,"","交易超限"),"该股票未持仓，仅可买入")) | J2: 股票名称 | K2: 总卖出股数 | L2: 总盈亏
A3: 2 | E3: =IF(B3="","",IF(D3<=0,-C3*D3*2.5/10000,C3*D3*12.5/10000)) | F3: =IF(B3="","",C3*D3-E3) | G3: =IF(B3="","",IF(COUNTIF(盘中持仓!B:B,B3),VLOOKUP(B3,盘中持仓!B:D,3,0),0)) | H3: =IF(B3="","",IF(G3<>0,IF(G3>0,"","交易超限"),"该股票未持仓，仅可买入")) | J3: 联创光电 | K3: -1500 | L3: -108319.57
A4: 3 | E4: =IF(B4="","",IF(D4<=0,-C4*D4*2.5/10000,C4*D4*12.5/10000)) | F4: =IF(B4="","",C4*D4-E4) | G4: =IF(B4="","",IF(COUNTIF(盘中持仓!B:B,B4),VLOOKUP(B4,盘中持仓!B:D,3,0),0)) | H4: =IF(B4="","",IF(G4<>0,IF(G4>0,"","交易超限"),"该股票未持仓，仅可买入")) | J4: 山东黄金 | K4: 2900 | L4: 124040.16
A5: 4 | E5: =IF(B5="","",IF(D5<=0,-C5*D5*2.5/10000,C5*D5*12.5/10000)) | F5: =IF(B5="","",C5*D5-E5) | G5: =IF(B5="","",IF(COUNTIF(盘中持仓!B:B,B5),VLOOKUP(B5,盘中持仓!B:D,3,0),0)) | H5: =IF(B5="","",IF(G5<>0,IF(G5>0,"","交易超限"),"该股票未持仓，仅可买入")) | J5: (空白) | L5: 0
A6: 5 | E6: =IF(B6="","",IF(D6<=0,-C6*D6*2.5/10000,C6*D6*12.5/10000)) | F6: =IF(B6="","",C6*D6-E6) | G6: =IF(B6="","",IF(COUNTIF(盘中持仓!B:B,B6),VLOOKUP(B6,盘中持仓!B:D,3,0),0)) | H6: =IF(B6="","",IF(G6<>0,IF(G6>0,"","交易超限"),"该股票未持仓，仅可买入")) | J6: 中芯国际 | K6: -1600 | L6: -207283.81
A7: 6 | E7: =IF(B7="","",IF(D7<=0,-C7*D7*2.5/10000,C7*D7*12.5/10000)) | F7: =IF(B7="","",C7*D7-E7) | G7: =IF(B7="","",IF(COUNTIF(盘中持仓!B:B,B7),VLOOKUP(B7,盘中持仓!B:D,3,0),0)) | H7: =IF(B7="","",IF(G7<>0,IF(G7>0,"","交易超限"),"该股票未持仓，仅可买入")) | J7: 宏微科技 | K7: 3000 | L7: 98786.363
A8: 7 | E8: =IF(B8="","",IF(D8<=0,-C8*D8*2.5/10000,C8*D8*12.5/10000)) | F8: =IF(B8="","",C8*D8-E8) | G8: =IF(B8="","",IF(COUNTIF(盘中持仓!B:B,B8),VLOOKUP(B8,盘中持仓!B:D,3,0),0)) | H8: =IF(B8="","",IF(G8<>0,IF(G8>0,"","交易超限"),"该股票未持仓，仅可买入")) | J8: 中微公司 | K8: -700 | L8: -236785.18
A9: 8 | E9: =IF(B9="","",IF(D9<=0,-C9*D9*2.5/10000,C9*D9*12.5/10000)) | F9: =IF(B9="","",C9*D9-E9) | G9: =IF(B9="","",IF(COUNTIF(盘中持仓!B:B,B9),VLOOKUP(B9,盘中持仓!B:D,3,0),0)) | H9: =IF(B9="","",IF(G9<>0,IF(G9>0,"","交易超限"),"该股票未持仓，仅可买入")) | J9: 国光电气 | K9: -1800 | L9: -204423.09
A10: 9 | E10: =IF(B10="","",IF(D10<=0,-C10*D10*2.5/10000,C10*D10*12.5/10000)) | F10: =IF(B10="","",C10*D10-E10) | G10: =IF(B10="","",IF(COUNTIF(盘中持仓!B:B,B10),VLOOKUP(B10,盘中持仓!B:D,3,0),0)) | H10: =IF(B10="","",IF(G10<>0,IF(G10>0,"","交易超限"),"该股票未持仓，仅可买入")) | J10: 斯达半导 | K10: 2000 | L10: 203373.46
A11: 10 | E11: =IF(B11="","",IF(D11<=0,-C11*D11*2.5/10000,C11*D11*12.5/10000)) | F11: =IF(B11="","",C11*D11-E11) | G11: =IF(B11="","",IF(COUNTIF(盘中持仓!B:B,B11),VLOOKUP(B11,盘中持仓!B:D,3,0),0)) | H11: =IF(B11="","",IF(G11<>0,IF(G11>0,"","交易超限"),"该股票未持仓，仅可买入")) | J11: 西部黄金 | K11: 7200 | L11: 206381.7
A12: 11 | E12: =IF(B12="","",IF(D12<=0,-C12*D12*2.5/10000,C12*D12*12.5/10000)) | F12: =IF(B12="","",C12*D12-E12) | G12: =IF(B12="","",IF(COUNTIF(盘中持仓!B:B,B12),VLOOKUP(B12,盘中持仓!B:D,3,0),0)) | H12: =IF(B12="","",IF(G12<>0,IF(G12>0,"","交易超限"),"该股票未持仓，仅可买入")) | J12: 总计 | K12: 9500 | L12: -124229.97
A13: 12 | E13: =IF(B13="","",IF(D13<=0,-C13*D13*2.5/10000,C13*D13*12.5/10000)) | F13: =IF(B13="","",C13*D13-E13) | G13: =IF(B13="","",IF(COUNTIF(盘中持仓!B:B,B13),VLOOKUP(B13,盘中持仓!B:D,3,0),0)) | H13: =IF(B13="","",IF(G13<>0,IF(G13>0,"","交易超限"),"该股票未持仓，仅可买入"))
A14: 13 | E14: =IF(B14="","",IF(D14<=0,-C14*D14*2.5/10000,C14*D14*12.5/10000)) | F14: =IF(B14="","",C14*D14-E14) | G14: =IF(B14="","",IF(COUNTIF(盘中持仓!B:B,B14),VLOOKUP(B14,盘中持仓!B:D,3,0),0)) | H14: =IF(B14="","",IF(G14<>0,IF(G14>0,"","交易超限"),"该股票未持仓，仅可买入"))
A15: 14 | E15: =IF(B15="","",IF(D15<=0,-C15*D15*2.5/10000,C15*D15*12.5/10000)) | F15: =IF(B15="","",C15*D15-E15) | G15: =IF(B15="","",IF(COUNTIF(盘中持仓!B:B,B15),VLOOKUP(B15,盘中持仓!B:D,3,0),0)) | H15: =IF(B15="","",IF(G15<>0,IF(G15>0,"","交易超限"),"该股票未持仓，仅可买入")) | L15: 4200 | M15: 29.54 | N15: 124084
A16: 15 | E16: =IF(B16="","",IF(D16<=0,-C16*D16*2.5/10000,C16*D16*12.5/10000)) | F16: =IF(B16="","",C16*D16-E16) | G16: =IF(B16="","",IF(COUNTIF(盘中持仓!B:B,B16),VLOOKUP(B16,盘中持仓!B:D,3,0),0)) | H16: =IF(B16="","",IF(G16<>0,IF(G16>0,"","交易超限"),"该股票未持仓，仅可买入")) | L16: 10900 | N16: 322520
A17: 16 | E17: =IF(B17="","",IF(D17<=0,-C17*D17*2.5/10000,C17*D17*12.5/10000)) | F17: =IF(B17="","",C17*D17-E17) | G17: =IF(B17="","",IF(COUNTIF(盘中持仓!B:B,B17),VLOOKUP(B17,盘中持仓!B:D,3,0),0)) | H17: =IF(B17="","",IF(G17<>0,IF(G17>0,"","交易超限"),"该股票未持仓，仅可买入")) | L17: =L16-L15 | M17: =N17/L17 | N17: =N16-N15
A18: 17 | E18: =IF(B18="","",IF(D18<=0,-C18*D18*2.5/10000,C18*D18*12.5/10000)) | F18: =IF(B18="","",C18*D18-E18) | G18: =IF(B18="","",IF(COUNTIF(盘中持仓!B:B,B18),VLOOKUP(B18,盘中持仓!B:D,3,0),0)) | H18: =IF(B18="","",IF(G18<>0,IF(G18>0,"","交易超限"),"该股票未持仓，仅可买入"))
A19: 18 | E19: =IF(B19="","",IF(D19<=0,-C19*D19*2.5/10000,C19*D19*12.5/10000)) | F19: =IF(B19="","",C19*D19-E19) | G19: =IF(B19="","",IF(COUNTIF(盘中持仓!B:B,B19),VLOOKUP(B19,盘中持仓!B:D,3,0),0)) | H19: =IF(B19="","",IF(G19<>0,IF(G19>0,"","交易超限"),"该股票未持仓，仅可买入"))
A20: 19 | E20: =IF(B20="","",IF(D20<=0,-C20*D20*2.5/10000,C20*D20*12.5/10000)) | F20: =IF(B20="","",C20*D20-E20) | G20: =IF(B20="","",IF(COUNTIF(盘中持仓!B:B,B20),VLOOKUP(B20,盘中持仓!B:D,3,0),0)) | H20: =IF(B20="","",IF(G20<>0,IF(G20>0,"","交易超限"),"该股票未持仓，仅可买入"))
A21: 20 | E21: =IF(B21="","",IF(D21<=0,-C21*D21*2.5/10000,C21*D21*12.5/10000)) | F21: =IF(B21="","",C21*D21-E21) | G21: =IF(B21="","",IF(COUNTIF(盘中持仓!B:B,B21),VLOOKUP(B21,盘中持仓!B:D,3,0),0)) | H21: =IF(B21="","",IF(G21<>0,IF(G21>0,"","交易超限"),"该股票未持仓，仅可买入"))
A22: 21 | E22: =IF(B22="","",IF(D22<=0,-C22*D22*2.5/10000,C22*D22*12.5/10000)) | F22: =IF(B22="","",C22*D22-E22) | G22: =IF(B22="","",IF(COUNTIF(盘中持仓!B:B,B22),VLOOKUP(B22,盘中持仓!B:D,3,0),0)) | H22: =IF(B22="","",IF(G22<>0,IF(G22>0,"","交易超限"),"该股票未持仓，仅可买入"))
A23: 22 | E23: =IF(B23="","",IF(D23<=0,-C23*D23*2.5/10000,C23*D23*12.5/10000)) | F23: =IF(B23="","",C23*D23-E23) | G23: =IF(B23="","",IF(COUNTIF(盘中持仓!B:B,B23),VLOOKUP(B23,盘中持仓!B:D,3,0),0)) | H23: =IF(B23="","",IF(G23<>0,IF(G23>0,"","交易超限"),"该股票未持仓，仅可买入"))
A24: 23 | E24: =IF(B24="","",IF(D24<=0,-C24*D24*2.5/10000,C24*D24*12.5/10000)) | F24: =IF(B24="","",C24*D24-E24) | G24: =IF(B24="","",IF(COUNTIF(盘中持仓!B:B,B24),VLOOKUP(B24,盘中持仓!B:D,3,0),0)) | H24: =IF(B24="","",IF(G24<>0,IF(G24>0,"","交易超限"),"该股票未持仓，仅可买入"))
A25: 24 | E25: =IF(B25="","",IF(D25<=0,-C25*D25*2.5/10000,C25*D25*12.5/10000)) | F25: =IF(B25="","",C25*D25-E25) | G25: =IF(B25="","",IF(COUNTIF(盘中持仓!B:B,B25),VLOOKUP(B25,盘中持仓!B:D,3,0),0)) | H25: =IF(B25="","",IF(G25<>0,IF(G25>0,"","交易超限"),"该股票未持仓，仅可买入"))
A26: 25 | E26: =IF(B26="","",IF(D26<=0,-C26*D26*2.5/10000,C26*D26*12.5/10000)) | F26: =IF(B26="","",C26*D26-E26) | G26: =IF(B26="","",IF(COUNTIF(盘中持仓!B:B,B26),VLOOKUP(B26,盘中持仓!B:D,3,0),0)) | H26: =IF(B26="","",IF(G26<>0,IF(G26>0,"","交易超限"),"该股票未持仓，仅可买入"))
A27: 26 | E27: =IF(B27="","",IF(D27<=0,-C27*D27*2.5/10000,C27*D27*12.5/10000)) | F27: =IF(B27="","",C27*D27-E27) | G27: =IF(B27="","",IF(COUNTIF(盘中持仓!B:B,B27),VLOOKUP(B27,盘中持仓!B:D,3,0),0)) | H27: =IF(B27="","",IF(G27<>0,IF(G27>0,"","交易超限"),"该股票未持仓，仅可买入"))
A28: 27 | E28: =IF(B28="","",IF(D28<=0,-C28*D28*2.5/10000,C28*D28*12.5/10000)) | F28: =IF(B28="","",C28*D28-E28) | G28: =IF(B28="","",IF(COUNTIF(盘中持仓!B:B,B28),VLOOKUP(B28,盘中持仓!B:D,3,0),0)) | H28: =IF(B28="","",IF(G28<>0,IF(G28>0,"","交易超限"),"该股票未持仓，仅可买入"))
A29: 28 | E29: =IF(B29="","",IF(D29<=0,-C29*D29*2.5/10000,C29*D29*12.5/10000)) | F29: =IF(B29="","",C29*D29-E29) | G29: =IF(B29="","",IF(COUNTIF(盘中持仓!B:B,B29),VLOOKUP(B29,盘中持仓!B:D,3,0),0)) | H29: =IF(B29="","",IF(G29<>0,IF(G29>0,"","交易超限"),"该股票未持仓，仅可买入"))
... A201: 200 | E201: =IF(B201="","",IF(D201<=0,-C201*D201*2.5/10000,C201*D201*12.5/10000)) | F201: =IF(B201="","",C201*D201-E201) | G201: =IF(B201="","",IF(COUNTIF(盘中持仓!B:B,B201),VLOOKUP(B201,盘中持仓!B:D,3,0),0)) | H201: =IF(B201="","",IF(G201<>0,IF(G201>0,"","交易超限"),"该股票未持仓，仅可买入"))

Sheet 盘中持仓
A1: 序号 | B1: 股票名称 | C1: 持仓成本 | D1: 持仓股数
A2: 1 | B2: =VLOOKUP(A2,持仓总表!A:B,2,0) | C2: =(持仓总表!H3*持仓总表!F3-SUMIF(当日交易记录!B:B,B2,当日交易记录!F:F))/D2 | D2: =持仓总表!F3-SUMIF(当日交易记录!B:B,B2,当日交易记录!D:D)
A3: 2 | B3: =VLOOKUP(A3,持仓总表!A:B,2,0) | C3: =(持仓总表!H4*持仓总表!F4-SUMIF(当日交易记录!B:B,B3,当日交易记录!F:F))/D3 | D3: =持仓总表!F4-SUMIF(当日交易记录!B:B,B3,当日交易记录!D:D)
A4: 3 | B4: =VLOOKUP(A4,持仓总表!A:B,2,0) | C4: =(持仓总表!H5*持仓总表!F5-SUMIF(当日交易记录!B:B,B4,当日交易记录!F:F))/D4 | D4: =持仓总表!F5-SUMIF(当日交易记录!B:B,B4,当日交易记录!D:D)
A5: 4 | B5: =VLOOKUP(A5,持仓总表!A:B,2,0) | C5: =(持仓总表!H6*持仓总表!F6-SUMIF(当日交易记录!B:B,B5,当日交易记录!F:F))/D5 | D5: =持仓总表!F6-SUMIF(当日交易记录!B:B,B5,当日交易记录!D:D)
A6: 5 | B6: =VLOOKUP(A6,持仓总表!A:B,2,0) | C6: =(持仓总表!H7*持仓总表!F7-SUMIF(当日交易记录!B:B,B6,当日交易记录!F:F))/D6 | D6: =持仓总表!F7-SUMIF(当日交易记录!B:B,B6,当日交易记录!D:D)
A7: 6 | B7: =VLOOKUP(A7,持仓总表!A:B,2,0) | C7: =(持仓总表!H8*持仓总表!F8-SUMIF(当日交易记录!B:B,B7,当日交易记录!F:F))/D7 | D7: =持仓总表!F8-SUMIF(当日交易记录!B:B,B7,当日交易记录!D:D)
A8: 7 | B8: =VLOOKUP(A8,持仓总表!A:B,2,0) | C8: =(持仓总表!H9*持仓总表!F9-SUMIF(当日交易记录!B:B,B8,当日交易记录!F:F))/D8 | D8: =持仓总表!F9-SUMIF(当日交易记录!B:B,B8,当日交易记录!D:D)
A9: 8 | B9: =VLOOKUP(A9,持仓总表!A:B,2,0) | C9: =(持仓总表!H10*持仓总表!F10-SUMIF(当日交易记录!B:B,B9,当日交易记录!F:F))/D9 | D9: =持仓总表!F10-SUMIF(当日交易记录!B:B,B9,当日交易记录!D:D)
A10: 9 | B10: =VLOOKUP(A10,持仓总表!A:B,2,0) | C10: =(持仓总表!H11*持仓总表!F11-SUMIF(当日交易记录!B:B,B10,当日交易记录!F:F))/D10 | D10: =持仓总表!F11-SUMIF(当日交易记录!B:B,B10,当日交易记录!D:D)
A11: 10 | B11: =VLOOKUP(A11,持仓总表!A:B,2,0) | C11: =(持仓总表!H12*持仓总表!F12-SUMIF(当日交易记录!B:B,B11,当日交易记录!F:F))/D11 | D11: =持仓总表!F12-SUMIF(当日交易记录!B:B,B11,当日交易记录!D:D)
A12: 11 | B12: =VLOOKUP(A12,持仓总表!A:B,2,0) | C12: =(持仓总表!H13*持仓总表!F13-SUMIF(当日交易记录!B:B,B12,当日交易记录!F:F))/D12 | D12: =持仓总表!F13-SUMIF(当日交易记录!B:B,B12,当日交易记录!D:D)
A13: 12 | B13: =VLOOKUP(A13,持仓总表!A:B,2,0) | C13: =(持仓总表!H14*持仓总表!F14-SUMIF(当日交易记录!B:B,B13,当日交易记录!F:F))/D13 | D13: =持仓总表!F14-SUMIF(当日交易记录!B:B,B13,当日交易记录!D:D)
... A20: 19 | B20: =VLOOKUP(A20,持仓总表!A:B,2,0) | C20: =(持仓总表!H21*持仓总表!F21-SUMIF(当日交易记录!B:B,B20,当日交易记录!F:F))/D20 | D20: =持仓总表!F21-SUMIF(当日交易记录!B:B,B20,当日交易记录!D:D)
A21: 20 | B21: =VLOOKUP(A21,持仓总表!A:B,2,0) | C21: =(持仓总表!H22*持仓总表!F22-SUMIF(当日交易记录!B:B,B21,当日交易记录!F:F))/D21 | D21: =持仓总表!F23-SUMIF(当日交易记录!B:B,B21,当日交易记录!D:D)
A22: 21 | B22: =VLOOKUP(A22,持仓总表!A:B,2,0) | C22: =(持仓总表!H23*持仓总表!F23-SUMIF(当日交易记录!B:B,B22,当日交易记录!F:F))/D22 | D22: =持仓总表!F24-SUMIF(当日交易记录!B:B,B22,当日交易记录!D:D)
A23: 22 | B23: =VLOOKUP(A23,持仓总表!A:B,2,0) | C23: =(持仓总表!H25*持仓总表!F25-SUMIF(当日交易记录!B:B,B23,当日交易记录!F:F))/D23 | D23: =持仓总表!F25-SUMIF(当日交易记录!B:B,B23,当日交易记录!D:D)
A24: 23 | B24: =VLOOKUP(A24,持仓总表!A:B,2,0) | C24: =(持仓总表!H26*持仓总表!F26-SUMIF(当日交易记录!B:B,B24,当日交易记录!F:F))/D24 | D24: =持仓总表!F26-SUMIF(当日交易记录!B:B,B24,当日交易记录!D:D)
A25: 24 | B25: =VLOOKUP(A25,持仓总表!A:B,2,0) | C25: =(持仓总表!H27*持仓总表!F27-SUMIF(当日交易记录!B:B,B25,当日交易记录!F:F))/D25 | D25: =持仓总表!F27-SUMIF(当日交易记录!B:B,B25,当日交易记录!D:D)
A26: 25 | B26: =VLOOKUP(A26,持仓总表!A:B,2,0) | C26: =(持仓总表!H28*持仓总表!F28-SUMIF(当日交易记录!B:B,B26,当日交易记录!F:F))/D26 | D26: =持仓总表!F28-SUMIF(当日交易记录!B:B,B26,当日交易记录!D:D)
A27: 26 | B27: =VLOOKUP(A27,持仓总表!A:B,2,0) | C27: =(持仓总表!H29*持仓总表!F29-SUMIF(当日交易记录!B:B,B27,当日交易记录!F:F))/D27 | D27: =持仓总表!F29-SUMIF(当日交易记录!B:B,B27,当日交易记录!D:D)
A28: 27 | B28: =VLOOKUP(A28,持仓总表!A:B,2,0) | C28: =(持仓总表!H30*持仓总表!F30-SUMIF(当日交易记录!B:B,B28,当日交易记录!F:F))/D28 | D28: =持仓总表!F30-SUMIF(当日交易记录!B:B,B28,当日交易记录!D:D)
A29: 28 | B29: =VLOOKUP(A29,持仓总表!A:B,2,0) | C29: =(持仓总表!H31*持仓总表!F31-SUMIF(当日交易记录!B:B,B29,当日交易记录!F:F))/D29 | D29: =持仓总表!F31-SUMIF(当日交易记录!B:B,B29,当日交易记录!D:D)
A30: 30 | B30: =VLOOKUP(A30,持仓总表!A:B,2,0) | C30: =(持仓总表!H32*持仓总表!F32-SUMIF(当日交易记录!B:B,B30,当日交易记录!F:F))/D30 | D30: =持仓总表!F32-SUMIF(当日交易记录!B:B,B30,当日交易记录!D:D)
A31: 31 | B31: =VLOOKUP(A31,持仓总表!A:B,2,0) | C31: =(持仓总表!H33*持仓总表!F33-SUMIF(当日交易记录!B:B,B31,当日交易记录!F:F))/D31 | D31: =持仓总表!F33-SUMIF(当日交易记录!B:B,B31,当日交易记录!D:D)
A32: 32 | B32: =VLOOKUP(A32,持仓总表!A:B,2,0) | C32: =(持仓总表!H34*持仓总表!F34-SUMIF(当日交易记录!B:B,B32,当日交易记录!F:F))/D32 | D32: =持仓总表!F34-SUMIF(当日交易记录!B:B,B32,当日交易记录!D:D)
A33: 33 | B33: =VLOOKUP(A33,持仓总表!A:B,2,0) | C33: =(持仓总表!H35*持仓总表!F35-SUMIF(当日交易记录!B:B,B33,当日交易记录!F:F))/D33 | D33: =持仓总表!F35-SUMIF(当日交易记录!B:B,B33,当日交易记录!D:D)
A34: 34 | B34: =VLOOKUP(A34,持仓总表!A:B,2,0) | C34: =(持仓总表!H36*持仓总表!F36-SUMIF(当日交易记录!B:B,B34,当日交易记录!F:F))/D34 | D34: =持仓总表!F36-SUMIF(当日交易记录!B:B,B34,当日交易记录!D:D)
... A200: 200 | B200: =VLOOKUP(A200,持仓总表!A:B,2,0) | C200: =(持仓总表!H202*持仓总表!F202-SUMIF(当日交易记录!B:B,B200,当日交易记录!F:F))/D200 | D200: =持仓总表!F202-SUMIF(当日交易记录!B:B,B200,当日交易记录!D:D)

Sheet 持仓成本
A1: 小组波段汇总表
A2: 序号 | B2: 股票名称 | C2: 盈亏比例 | D2: 持仓成本 | E2: 持仓市值 | F2: 持仓股数 | G2: 现价 | H2: 成本价 | I2: 盈亏额
A3: 1 | B3: 国光电气 | C3: =I3/D3 | D3: =H3*F3 | E3: =G3*F3 | F3: 2700 | G3: 130.2 | H3: 131.5 | I3: =E3-D3
A4: 2 | C4: =I4/D4 | D4: =H4*F4 | E4: =G4*F4 | F4: 13800 | I4: =E4-D4
A5: 3 | C5: =I5/D5 | D5: =H5*F5 | E5: =G5*F5 | F5: 3500 | I5: =E5-D5
A6: 4 | C6: =I6/D6 | D6: =H6*F6 | E6: =G6*F6 | F6: 7300 | I6: =E6-D6
A7: 5 | C7: =I7/D7 | D7: =H7*F7 | E7: =G7*F7 | F7: 6548 | I7: =E7-D7
A8: 6 | C8: =I8/D8 | D8: =H8*F8 | E8: =G8*F8 | F8: 3900 | I8: =E8-D8
A9: 7 | C9: =I9/D9 | D9: =H9*F9 | E9: =G9*F9 | F9: 19300 | I9: =E9-D9
A10: 8 | C10: =I10/D10 | D10: =H10*F10 | E10: =G10*F10 | F10: 1300 | I10: =E10-D10
A11: 9 | C11: =I11/D11 | D11: =H11*F11 | E11: =G11*F11 | F11: 2500 | I11: =E11-D11
A12: 10 | C12: =I12/D12 | D12: =H12*F12 | E12: =G12*F12 | F12: 5700 | I12: =E12-D12
A13: 11 | C13: =I13/D13 | D13: =H13*F13 | E13: =G13*F13 | F13: 3600 | I13: =E13-D13
A14: 12 | C14: =I14/D14 | D14: =H14*F14 | E14: =G14*F14 | F14: 1000 | I14: =E14-D14
A15: 13 | C15: =I15/D15 | D15: =H15*F15 | E15: =G15*F15 | I15: =E15-D15
A16: 合计 | C16: 0.16755383 | D16: =SUM(D3:D15) | E16: =SUM(E3:E15) | F16: =SUM(F3:F15) | I16: 605214.49
I17: 605214.49
I18: 0
